<?xml version="1.0" ?>
<!-- =================================================================================== -->
<!-- |    This document was autogenerated by xacro from arter_main.xacro               | -->
<!-- |    EDITING THIS FILE BY HAND IS NOT RECOMMENDED                                 | -->
<!-- =================================================================================== -->
<robot name="arter">
  <!-- Option for prefix -->
  <!-- prefix holds the user input arg -->
  <!-- prefix holds the user input arg with the / at the end -->
  <!-- Please make sure to provide visual, collision, shovel and prefix properties before calling this file -->
  <link name="arter/base_link">
  </link>
  <link name="arter/base_inertial_link">
    <inertial>
      <origin rpy="0 0 0" xyz="0.01459 0.00031795 0.14907"/>
      <mass value="123.74"/>
      <inertia ixx="9.6513" ixy="-0.014972" ixz="-0.028087" iyy="8.722" iyz="-2.1382E-05" izz="17.448"/>
    </inertial>
    <visual>
      <origin rpy="0 0 0" xyz="0 0 0"/>
      <geometry>
        <mesh filename="package://m545_description/meshes/simplified/base_link.STL"/>
      </geometry>
      <material name="">
        <color rgba="0.75294 0.75294 0.75294 1"/>
      </material>
    </visual>
    <collision>
      <origin rpy="0 0 0" xyz="0 0 0"/>
      <geometry>
        <mesh filename="package://m545_description/meshes/convexhull/base_link.STL"/>
      </geometry>
    </collision>
  </link>
  <joint name="base_link_inertial_fixed" type="fixed">
    <origin rpy="0 0 0" xyz="0 0 0"/>
    <parent link="arter/base_link"/>
    <child link="arter/base_inertial_link"/>
  </joint>
  <link name="arter/cabin_link">
    <inertial>
      <origin rpy="0 0 0" xyz="-0.14578460324376 0.187220989063321 1.07940921573334"/>
      <mass value="176.199654517711"/>
      <inertia ixx="21.9741408601733" ixy="-1.41535049424902" ixz="2.23201529293403" iyy="21.3882207135514" iyz="-0.00756180222056317" izz="27.0066252235924"/>
    </inertial>
    <visual name="cabin_visual">
      <origin rpy="0 0 0" xyz="0 0 0"/>
      <geometry>
        <mesh filename="package://m545_description/meshes/simplified/cabin_link.dae"/>
      </geometry>
      <material name="">
        <color rgba="0.752941176470588 0.752941176470588 0.752941176470588 1"/>
      </material>
    </visual>
    <collision>
      <origin rpy="0 0 0" xyz="0 0 0"/>
      <geometry>
        <mesh filename="package://m545_description/meshes/convexhull/cabin_link.STL"/>
      </geometry>
    </collision>
  </link>
  <joint name="cabin" type="continuous">
    <origin rpy="0 0 0" xyz="0 0 0.444"/>
    <parent link="arter/base_link"/>
    <child link="arter/cabin_link"/>
    <axis xyz="0 0 1"/>
    <!-- <limit lower="-3.15" upper="3.15" effort="1200000" velocity="1"/> -->
    <limit effort="1200000" velocity="1"/>
  </joint>
  <link name="arter/boom_link">
    <inertial>
      <origin rpy="0 0 0" xyz="1.1489476459711 -0.0837175895770594 -0.000339766526676832"/>
      <mass value="78.4264149245442"/>
      <inertia ixx="1.27313214927495" ixy="-0.697544942268417" ixz="-0.0137969167573708" iyy="10.9268291362064" iyz="-0.000273252303950335" izz="11.885338848564"/>
    </inertial>
    <visual>
      <origin rpy="0 0 0" xyz="0 0 0"/>
      <geometry>
        <mesh filename="package://m545_description/meshes/simplified/boom_link.STL"/>
      </geometry>
      <material name="SignalBlue">
        <color rgba="0.117647059 0.176470588 0.431372549 1"/>
      </material>
    </visual>
    <collision>
      <origin rpy="0 0 0" xyz="0 0 0"/>
      <geometry>
        <mesh filename="package://m545_description/meshes/convexhull/boom_link.STL"/>
      </geometry>
    </collision>
  </link>
  <joint name="boom" type="revolute">
    <origin rpy="1.5708 0 0" xyz="0.69784 -0.28 0.633"/>
    <parent link="arter/cabin_link"/>
    <child link="arter/boom_link"/>
    <axis xyz="0 0 1"/>
    <limit effort="1200000" lower="-0.1" upper="1.27539443969727" velocity="1"/>
  </joint>
  <link name="arter/dipper_link">
    <inertial>
      <origin rpy="0 0 0" xyz="0.252258434907862 -0.188754073037101 -0.000989862865848457"/>
      <mass value="42.9898958771485"/>
      <inertia ixx="14.3755187707745" ixy="0.124177304961182" ixz="-1.43048203431484E-05" iyy="0.807144100483684" iyz="-4.50912409511463E-05" izz="14.598142888427"/>
    </inertial>
    <visual>
      <origin rpy="0 0 0" xyz="0 0 0"/>
      <geometry>
        <mesh filename="package://m545_description/meshes/simplified/dipper_link.STL"/>
      </geometry>
      <material name="SignalBlue">
        <color rgba="0.117647059 0.176470588 0.431372549 1"/>
      </material>
    </visual>
    <collision>
      <origin rpy="0 0 0" xyz="0 0 0"/>
      <geometry>
        <mesh filename="package://m545_description/meshes/convexhull/dipper_link.STL" scale="1.0 1.0 1.0"/>
      </geometry>
    </collision>
  </link>
  <joint name="dipper" type="revolute">
    <origin rpy="0 0 0" xyz="2.85 0 0"/>
    <parent link="arter/boom_link"/>
    <child link="arter/dipper_link"/>
    <axis xyz="0 0 1"/>
    <limit effort="1200000" lower="-1.1" upper="1.00855886936188" velocity="1"/>
  </joint>
  <link name="arter/telescope_link">
    <inertial>
      <origin rpy="0 0 0" xyz="0.115484330078715 -0.0269173961886909 -0.589279474352937"/>
      <mass value="50.2217428894516"/>
      <inertia ixx="21.6810368760393" ixy="-0.000774746906639158" ixz="0.344150274509863" iyy="21.939633480392" iyz="-0.01245173866975" izz="0.448495529193911"/>
    </inertial>
    <visual>
      <origin rpy="0 0 0" xyz="0 0 0"/>
      <geometry>
        <mesh filename="package://m545_description/meshes/simplified/telescope_link.STL"/>
      </geometry>
      <material name="SignalBlue">
        <color rgba="0.117647059 0.176470588 0.431372549 1"/>
      </material>
    </visual>
    <collision>
      <origin rpy="0 0 0" xyz="0 0 0"/>
      <geometry>
        <mesh filename="package://m545_description/meshes/convexhull/telescope_link.STL" scale="1.0 1.0 1.0"/>
      </geometry>
    </collision>
  </link>
  <joint name="telescope" type="prismatic">
    <origin rpy="1.5708 0 0" xyz="0.336 -1.4555 0"/>
    <parent link="arter/dipper_link"/>
    <child link="arter/telescope_link"/>
    <axis xyz="0 0 1"/>
    <limit effort="1200000" lower="-0.0310199968516826" upper="1.76909995079041" velocity="1"/>
  </joint>
  <link name="arter/shovel_link">
    <inertial>
      <origin rpy="0 0 0" xyz="0.308636829526959 -0.073678159857208 0.00265947518420701"/>
      <mass value="30.6924117821897"/>
      <inertia ixx="0.601622091727508" ixy="0.0975263819884591" ixz="0.00122727157785062" iyy="1.75837217940506" iyz="0.00436173902393642" izz="1.42275640797648"/>
    </inertial>
    <visual>
      <origin rpy="0 0 0" xyz="0 0 0"/>
      <geometry>
        <mesh filename="package://m545_description/meshes/simplified/shovel_link.STL"/>
      </geometry>
      <material name="SignalBlue">
        <color rgba="0.117647059 0.176470588 0.431372549 1"/>
      </material>
    </visual>
    <collision>
      <origin rpy="0 0 0" xyz="0 0 0"/>
      <geometry>
        <mesh filename="package://m545_description/meshes/convexhull/shovel_link.STL" scale="1.0 1.0 1.0"/>
      </geometry>
    </collision>
  </link>
  <joint name="shovel" type="revolute">
    <origin rpy="-1.5708 0 0" xyz="0.03 0 0.53"/>
    <parent link="arter/telescope_link"/>
    <child link="arter/shovel_link"/>
    <axis xyz="0 0 1"/>
    <limit effort="1200000" lower="-2.295" upper="0.641655027866364" velocity="1"/>
  </joint>
  <link name="arter/tilt_link">
    <inertial>
      <origin rpy="0 0 0" xyz="-0.0992693656464256 -0.00328060710549277 0.0158053531697835"/>
      <mass value="49.2376631166149"/>
      <inertia ixx="1.4979866014152" ixy="-0.00915814834409523" ixz="-0.00421757376964278" iyy="1.03937814018178" iyz="0.0313220319827188" izz="0.596282576583931"/>
    </inertial>
    <visual>
      <origin rpy="0 0 0" xyz="0 0 0"/>
      <geometry>
        <mesh filename="package://m545_description/meshes/simplified/tilt_link.STL"/>
      </geometry>
      <material name="Red">
        <color rgba="0.752941176470588 0.0 0.0 1"/>
      </material>
    </visual>
    <collision>
      <origin rpy="0 0 0" xyz="0 0 0"/>
      <geometry>
        <mesh filename="package://m545_description/meshes/convexhull/tilt_link.STL" scale="1.0 1.0 1.0"/>
      </geometry>
    </collision>
  </link>
  <joint name="tilt" type="revolute">
    <origin rpy="1.5708 0 1.5708" xyz="0.3645 -0.238 0"/>
    <parent link="arter/shovel_link"/>
    <child link="arter/tilt_link"/>
    <axis xyz="0 0 1"/>
    <limit effort="1200000" lower="-0.68" upper="0.68" velocity="1"/>
  </joint>
  <link name="arter/roto_link">
    <inertial>
      <origin rpy="0 0 0" xyz="-0.0294150050950259 0.000102719411839813 -0.0699235737416475"/>
      <mass value="30.0178957422352"/>
      <inertia ixx="0.361948521496818" ixy="-7.52138370521607E-05" ixz="0.0142407241776525" iyy="0.590582184962137" iyz="4.94979911380229E-05" izz="0.772634756313473"/>
    </inertial>
    <visual>
      <origin rpy="0 0 0" xyz="0 0 0"/>
      <geometry>
        <mesh filename="package://m545_description/meshes/simplified/roto_link.STL"/>
      </geometry>
      <material name="Red">
        <color rgba="0.752941176470588 0.0 0.0 1"/>
      </material>
    </visual>
    <collision>
      <origin rpy="0 0 0" xyz="0 0 0"/>
      <geometry>
        <mesh filename="package://m545_description/meshes/convexhull/roto_link.STL" scale="1.0 1.0 1.0"/>
      </geometry>
    </collision>
  </link>
  <joint name="roto" type="continuous">
    <origin rpy="0.026702 -1.5708 3.1149" xyz="-0.17865 0 -0.0225"/>
    <!--origin xyz="-0.17865 0 -0.0225" rpy="0 1.5708 0"/-->
    <parent link="arter/tilt_link"/>
    <child link="arter/roto_link"/>
    <axis xyz="0 0 1"/>
    <!-- lower="-3.15" upper="4.00" -->
    <limit effort="1200000" velocity="1"/>
  </joint>
  <link name="arter/tool_link"/>
  <joint name="tool_fixed" type="fixed">
    <origin rpy="1.5708 0 0" xyz="-0.201 0 -0.1165"/>
    <parent link="arter/roto_link"/>
    <child link="arter/tool_link"/>
    <axis xyz="0 0 0"/>
  </joint>
  <link name="arter/imu_cover_target_link">
  </link>
  <joint name="imu_cover_target_joint_fixed" type="fixed">
    <origin rpy="-3.1416 -0.052391 0" xyz="0.03331 0.766 0.58067"/>
    <parent link="arter/cabin_link"/>
    <child link="arter/imu_cover_target_link"/>
    <axis xyz="0 0 0"/>
  </joint>
  <link name="arter/imu_output_link">
  </link>
  <joint name="imu_output_joint_fixed" type="fixed">
    <origin rpy="0 0 0" xyz="0 0 -0.444"/>
    <parent link="arter/cabin_link"/>
    <child link="arter/imu_output_link"/>
    <axis xyz="0 0 0"/>
  </joint>
  <link name="arter/swivel_fl_link">
    <inertial>
      <origin rpy="0 0 0" xyz="0.162995052062064 -0.0199376754001535 0.0487568927702829"/>
      <mass value="15.0689826221967"/>
      <inertia ixx="0.561000238049566" ixy="-0.0558414227116611" ixz="-0.0242986906318426" iyy="0.800587259999431" iyz="0.0417572698664409" izz="0.518019333968924"/>
    </inertial>
    <visual>
      <origin rpy="0 0 0" xyz="0 0 0"/>
      <geometry>
        <mesh filename="package://m545_description/meshes/simplified/swivel_fl_link.STL"/>
      </geometry>
      <material name="">
        <color rgba="0.752941176470588 0.752941176470588 0.752941176470588 1"/>
      </material>
    </visual>
    <collision>
      <origin rpy="0 0 0" xyz="0 0 0"/>
      <geometry>
        <mesh filename="package://m545_description/meshes/convexhull/swivel_fl_link.STL"/>
      </geometry>
    </collision>
  </link>
  <joint name="swivel_fl" type="revolute">
    <origin rpy="0 0 0" xyz="0.55 0.85 0.1335"/>
    <parent link="arter/base_link"/>
    <child link="arter/swivel_fl_link"/>
    <axis xyz="0 0 1"/>
    <limit effort="1200000" lower="-0.52" upper="0.75" velocity="1"/>
  </joint>
  <link name="arter/stabilizer_fl_link">
    <inertial>
      <origin rpy="0 0 0" xyz="0.614163674555745 -0.00619847606941248 3.51310055287657E-05"/>
      <mass value="28.6057125918348"/>
      <inertia ixx="0.198415957761357" ixy="0.000513487560518963" ixz="-4.47639900596476E-06" iyy="1.42973794379823" iyz="-7.97797154557726E-08" izz="1.52992895372242"/>
    </inertial>
    <visual>
      <origin rpy="0 0 0" xyz="0 0 0"/>
      <geometry>
        <mesh filename="package://m545_description/meshes/simplified/stabilizer_fl_link.STL"/>
      </geometry>
      <material name="">
        <color rgba="0.752941176470588 0.752941176470588 0.752941176470588 1"/>
      </material>
    </visual>
    <collision>
      <origin rpy="0 0 0" xyz="0 0 0"/>
      <geometry>
        <mesh filename="package://m545_description/meshes/convexhull/stabilizer_fl_link.STL"/>
      </geometry>
    </collision>
  </link>
  <joint name="stabilizer_fl" type="revolute">
    <origin rpy="1.5708 0 0" xyz="0.28 0 -0.0895"/>
    <parent link="arter/swivel_fl_link"/>
    <child link="arter/stabilizer_fl_link"/>
    <axis xyz="0 0 1"/>
    <limit effort="1200000" lower="-0.83" upper="0.29" velocity="1"/>
  </joint>
  <link name="arter/stabilizer_fl_mimic_link">
    <inertial>
      <origin rpy="0 0 0" xyz="0.14893281096356 0.0527862117810751 -0.0458288041206946"/>
      <mass value="13.4839940993509"/>
      <inertia ixx="0.212186802767068" ixy="-0.02102903417677" ixz="0.0172808782706694" iyy="0.159517147513103" iyz="0.000260348417950449" izz="0.143389060524418"/>
    </inertial>
    <visual>
      <origin rpy="0 0 0" xyz="0 0 0"/>
      <geometry>
        <mesh filename="package://m545_description/meshes/simplified/stabilizer_fl_mimic_link.STL"/>
      </geometry>
      <material name="">
        <color rgba="0.752941176470588 0.752941176470588 0.752941176470588 1"/>
      </material>
    </visual>
    <collision>
      <origin rpy="0 0 0" xyz="0 0 0"/>
      <geometry>
        <mesh filename="package://m545_description/meshes/convexhull/stabilizer_fl_mimic_link.STL"/>
      </geometry>
    </collision>
  </link>
  <joint name="stabilizer_fl_mimic" type="revolute">
    <origin rpy="0 0 0" xyz="1.2 0 0"/>
    <parent link="arter/stabilizer_fl_link"/>
    <child link="arter/stabilizer_fl_mimic_link"/>
    <axis xyz="0 0 1"/>
    <limit effort="0" lower="0" upper="0" velocity="0"/>
    <mimic joint="stabilizer_fl" multiplier="-1" offset="0"/>
  </joint>
  <link name="arter/steering_fl_link">
    <inertial>
      <origin rpy="0 0 0" xyz="0.252069524736596 0.12345347776231 -0.000196551625110342"/>
      <mass value="12.8650008327271"/>
      <inertia ixx="0.173596082439541" ixy="-0.00265936139183024" ixz="-1.71089081341986E-05" iyy="0.23408210019296" iyz="-0.000287228662378927" izz="0.200275636196243"/>
    </inertial>
    <visual>
      <origin rpy="0 0 0" xyz="0 0 0"/>
      <geometry>
        <mesh filename="package://m545_description/meshes/simplified/steering_fl_link.STL"/>
      </geometry>
      <material name="">
        <color rgba="0.752941176470588 0.752941176470588 0.752941176470588 1"/>
      </material>
    </visual>
    <collision>
      <origin rpy="0 0 0" xyz="0 0 0"/>
      <geometry>
        <mesh filename="package://m545_description/meshes/convexhull/steering_fl_link.STL"/>
      </geometry>
    </collision>
  </link>
  <joint name="steering_fl" type="revolute">
    <origin rpy="-1.5708 0 0" xyz="0.235 -0.003 -0.298"/>
    <parent link="arter/stabilizer_fl_mimic_link"/>
    <child link="arter/steering_fl_link"/>
    <axis xyz="0 0 1"/>
    <limit effort="1200000" lower="-0.87" upper="0.75" velocity="1"/>
  </joint>
  <link name="arter/wheel_fl_link">
    <inertial>
      <origin rpy="0 0 0" xyz="0.000223047967930157 0.000262523222543387 0.103929520980821"/>
      <mass value="154.123629069375"/>
      <inertia ixx="18.9060748943585" ixy="-0.00253557615931865" ixz="0.00311850863048898" iyy="18.9047872555934" iyz="0.00425425216647528" izz="28.6355025565708"/>
    </inertial>
    <visual>
      <origin rpy="0 0 0" xyz="0 0 0"/>
      <geometry>
        <mesh filename="package://m545_description/meshes/simplified/wheel_fl_link.dae"/>
      </geometry>
      <material name="">
        <color rgba="0.752941176470588 0.752941176470588 0.752941176470588 1"/>
      </material>
    </visual>
    <collision>
      <origin rpy="0 0 0" xyz="0 0 0"/>
      <geometry>
        <mesh filename="package://m545_description/meshes/convexhull/wheel_fl_link.STL" scale="1.1 1.1 1.1"/>
      </geometry>
    </collision>
  </link>
  <joint name="wheel_fl" type="continuous">
    <origin rpy="-1.5708 0 0" xyz="0.27 0.373 0"/>
    <parent link="arter/steering_fl_link"/>
    <child link="arter/wheel_fl_link"/>
    <axis xyz="0 0 1"/>
    <limit effort="1200000" velocity="10"/>
  </joint>
  <link name="arter/stabilizer_fl_parallel_mimic_link">
    <inertial>
      <origin rpy="0 0 0" xyz="0.612227927770633 0.0167931787809641 -0.00138630922427307"/>
      <mass value="6.87258948646713"/>
      <inertia ixx="0.0122067640666073" ixy="-0.000227130339417622" ixz="3.05482765545679E-08" iyy="0.778840873214655" iyz="9.66379804815663E-09" izz="0.772740535135119"/>
    </inertial>
    <visual>
      <origin rpy="0 0 0" xyz="0 0 0"/>
      <geometry>
        <mesh filename="package://m545_description/meshes/simplified/stabilizer_fl_parallel_mimic_link.STL"/>
      </geometry>
      <material name="">
        <color rgba="0.752941176470588 0.752941176470588 0.752941176470588 1"/>
      </material>
    </visual>
    <collision>
      <origin rpy="0 0 0" xyz="0 0 0"/>
      <geometry>
        <mesh filename="package://m545_description/meshes/convexhull/stabilizer_fl_parallel_mimic_link.STL"/>
      </geometry>
    </collision>
  </link>
  <joint name="stabilizer_fl_parallel_mimic" type="revolute">
    <origin rpy="1.5708 0 0" xyz="0.425 0 0.2105"/>
    <parent link="arter/swivel_fl_link"/>
    <child link="arter/stabilizer_fl_parallel_mimic_link"/>
    <axis xyz="0 0 1"/>
    <limit effort="0" lower="0" upper="0" velocity="0"/>
    <mimic joint="stabilizer_fl" multiplier="1" offset="0"/>
  </joint>
  <link name="arter/swivel_fr_link">
    <inertial>
      <origin rpy="0 0 0" xyz="0.162986256123228 0.0199346342076674 0.0487696670949589"/>
      <mass value="15.0632113131291"/>
      <inertia ixx="0.560873573271694" ixy="0.0557742144379766" ixz="-0.0243612860121339" iyy="0.800358360726816" iyz="-0.0417433355224152" izz="0.517856529420672"/>
    </inertial>
    <visual>
      <origin rpy="0 0 0" xyz="0 0 0"/>
      <geometry>
        <mesh filename="package://m545_description/meshes/simplified/swivel_fr_link.STL"/>
      </geometry>
      <material name="">
        <color rgba="0.752941176470588 0.752941176470588 0.752941176470588 1"/>
      </material>
    </visual>
    <collision>
      <origin rpy="0 0 0" xyz="0 0 0"/>
      <geometry>
        <mesh filename="package://m545_description/meshes/convexhull/swivel_fr_link.STL"/>
      </geometry>
    </collision>
  </link>
  <joint name="swivel_fr" type="revolute">
    <origin rpy="0 0 0" xyz="0.55 -0.85 0.1335"/>
    <parent link="arter/base_link"/>
    <child link="arter/swivel_fr_link"/>
    <axis xyz="0 0 1"/>
    <limit effort="1200000" lower="-0.81" upper="0.49" velocity="1"/>
  </joint>
  <link name="arter/stabilizer_fr_link">
    <inertial>
      <origin rpy="0 0 0" xyz="0.614163674561642 -0.00619847606755664 3.51310088779755E-05"/>
      <mass value="28.6057125922607"/>
      <inertia ixx="0.198415957762346" ixy="0.000513487561156539" ixz="-4.4763985571266E-06" iyy="1.42973794379811" iyz="-7.97797948753892E-08" izz="1.52992895372082"/>
    </inertial>
    <visual>
      <origin rpy="0 0 0" xyz="0 0 0"/>
      <geometry>
        <mesh filename="package://m545_description/meshes/simplified/stabilizer_fr_link.STL"/>
      </geometry>
      <material name="">
        <color rgba="0.752941176470588 0.752941176470588 0.752941176470588 1"/>
      </material>
    </visual>
    <collision>
      <origin rpy="0 0 0" xyz="0 0 0"/>
      <geometry>
        <mesh filename="package://m545_description/meshes/convexhull/stabilizer_fr_link.STL"/>
      </geometry>
    </collision>
  </link>
  <joint name="stabilizer_fr" type="revolute">
    <origin rpy="1.5708 0 0" xyz="0.28 0 -0.0895"/>
    <parent link="arter/swivel_fr_link"/>
    <child link="arter/stabilizer_fr_link"/>
    <axis xyz="0 0 1"/>
    <limit effort="1200000" lower="-0.83" upper="0.29" velocity="1"/>
  </joint>
  <link name="arter/stabilizer_fr_mimic_link">
    <inertial>
      <origin rpy="0 0 0" xyz="0.148935516707567 0.0527891396846881 0.0458138725621554"/>
      <mass value="13.4832381758141"/>
      <inertia ixx="0.212177916165869" ixy="-0.0210289413617358" ixz="-0.0172808811466097" iyy="0.159517076388514" iyz="-0.000260320262779366" izz="0.143380116218611"/>
    </inertial>
    <visual>
      <origin rpy="0 0 0" xyz="0 0 0"/>
      <geometry>
        <mesh filename="package://m545_description/meshes/simplified/stabilizer_fr_mimic_link.STL"/>
      </geometry>
      <material name="">
        <color rgba="0.752941176470588 0.752941176470588 0.752941176470588 1"/>
      </material>
    </visual>
    <collision>
      <origin rpy="0 0 0" xyz="0 0 0"/>
      <geometry>
        <mesh filename="package://m545_description/meshes/convexhull/stabilizer_fr_mimic_link.STL"/>
      </geometry>
    </collision>
  </link>
  <joint name="stabilizer_fr_mimic" type="revolute">
    <origin rpy="0 0 0" xyz="1.2 0 0"/>
    <parent link="arter/stabilizer_fr_link"/>
    <child link="arter/stabilizer_fr_mimic_link"/>
    <axis xyz="0 0 1"/>
    <limit effort="0" lower="0" upper="0" velocity="0"/>
    <mimic joint="stabilizer_fr" multiplier="-1" offset="0"/>
  </joint>
  <link name="arter/steering_fr_link">
    <inertial>
      <origin rpy="0 0 0" xyz="0.252069524736598 -0.123453477762308 -0.000163917144026526"/>
      <mass value="12.8650008327271"/>
      <inertia ixx="0.173596082439541" ixy="0.00265936139183019" ixz="1.71089081341666E-05" iyy="0.234082100192961" iyz="0.000333766992284394" izz="0.200275636196244"/>
    </inertial>
    <visual>
      <origin rpy="0 0 0" xyz="0 0 0"/>
      <geometry>
        <mesh filename="package://m545_description/meshes/simplified/steering_fr_link.STL"/>
      </geometry>
      <material name="">
        <color rgba="0.752941176470588 0.752941176470588 0.752941176470588 1"/>
      </material>
    </visual>
    <collision>
      <origin rpy="0 0 0" xyz="0 0 0"/>
      <geometry>
        <mesh filename="package://m545_description/meshes/convexhull/steering_fr_link.STL"/>
      </geometry>
    </collision>
  </link>
  <joint name="steering_fr" type="revolute">
    <origin rpy="-1.5708 0 0" xyz="0.235 -0.003 0.298"/>
    <parent link="arter/stabilizer_fr_mimic_link"/>
    <child link="arter/steering_fr_link"/>
    <axis xyz="0 0 1"/>
    <limit effort="1200000" lower="-0.78" upper="0.86" velocity="1"/>
  </joint>
  <link name="arter/wheel_fr_link">
    <inertial>
      <origin rpy="0 0 0" xyz="-9.49813900832375E-05 -0.000393346095014957 0.0307738390850882"/>
      <mass value="154.123028278742"/>
      <inertia ixx="18.9060063676975" ixy="0.000437544269841439" ixz="0.00169340835821026" iyy="18.9048523190307" iyz="-0.00404280334573332" izz="28.635202743547"/>
    </inertial>
    <visual>
      <origin rpy="0 0 0" xyz="0 0 0"/>
      <geometry>
        <mesh filename="package://m545_description/meshes/simplified/wheel_fr_link.dae"/>
      </geometry>
      <material name="">
        <color rgba="0.752941176470588 0.752941176470588 0.752941176470588 1"/>
      </material>
    </visual>
    <collision>
      <origin rpy="0 0 0" xyz="0 0 0"/>
      <geometry>
        <mesh filename="package://m545_description/meshes/convexhull/wheel_fr_link.STL" scale="1.1 1.1 1.1"/>
      </geometry>
    </collision>
  </link>
  <joint name="wheel_fr" type="continuous">
    <origin rpy="-1.5708 0.62959 3.1416" xyz="0.27 -0.40984 0"/>
    <parent link="arter/steering_fr_link"/>
    <child link="arter/wheel_fr_link"/>
    <axis xyz="0 0 1"/>
    <limit effort="1200000" velocity="10"/>
  </joint>
  <link name="arter/stabilizer_fr_parallel_mimic_link">
    <inertial>
      <origin rpy="0 0 0" xyz="0.612228198454034 0.0167931787843316 0.00204455059589392"/>
      <mass value="6.87258948661763"/>
      <inertia ixx="0.0122067640675326" ixy="-0.00022718099680906" ixz="3.0549833547656E-08" iyy="0.778840873216776" iyz="9.67032733845949E-09" izz="0.772740535136766"/>
    </inertial>
    <visual>
      <origin rpy="0 0 0" xyz="0 0 0"/>
      <geometry>
        <mesh filename="package://m545_description/meshes/simplified/stabilizer_fr_parallel_mimic_link.STL"/>
      </geometry>
      <material name="">
        <color rgba="0.752941176470588 0.752941176470588 0.752941176470588 1"/>
      </material>
    </visual>
    <collision>
      <origin rpy="0 0 0" xyz="0 0 0"/>
      <geometry>
        <mesh filename="package://m545_description/meshes/convexhull/stabilizer_fr_parallel_mimic_link.STL"/>
      </geometry>
    </collision>
  </link>
  <joint name="stabilizer_fr_parallel_mimic" type="revolute">
    <origin rpy="1.5708 0 0" xyz="0.425 0 0.2105"/>
    <parent link="arter/swivel_fr_link"/>
    <child link="arter/stabilizer_fr_parallel_mimic_link"/>
    <axis xyz="0 0 1"/>
    <limit effort="0" lower="0" upper="0" velocity="0"/>
    <mimic joint="stabilizer_fr" multiplier="1" offset="0"/>
  </joint>
  <link name="arter/stabilizer_rl_link">
    <inertial>
      <origin rpy="0 0 0" xyz="0.0882179070278704 0.140055763682226 0.00277591775711905"/>
      <mass value="13.9599595654884"/>
      <inertia ixx="0.16000906562063" ixy="0.00339485211765151" ixz="0.000294202110557503" iyy="0.118607367385089" iyz="0.00164260996387457" izz="0.0975616247733634"/>
    </inertial>
    <visual>
      <origin rpy="0 0 0" xyz="0 0 0"/>
      <geometry>
        <mesh filename="package://m545_description/meshes/simplified/stabilizer_rl_link.STL"/>
      </geometry>
      <material name="">
        <color rgba="0.752941176470588 0.752941176470588 0.752941176470588 1"/>
      </material>
    </visual>
    <collision>
      <origin rpy="0 0 0" xyz="0 0 0"/>
      <geometry>
        <mesh filename="package://m545_description/meshes/convexhull/stabilizer_rl_link.STL"/>
      </geometry>
    </collision>
  </link>
  <joint name="stabilizer_rl" type="revolute">
    <origin rpy="1.5708 0 -3.1416" xyz="-0.64 0.755 0.06"/>
    <parent link="arter/base_link"/>
    <child link="arter/stabilizer_rl_link"/>
    <axis xyz="0 0 1"/>
    <limit effort="1200000" lower="-0.77" upper="0.27" velocity="1"/>
  </joint>
  <link name="arter/swivel_rl_link">
    <inertial>
      <origin rpy="0 0 0" xyz="0.51033080116725 0.0805007276649072 -0.011272568783005"/>
      <mass value="22.066076001064"/>
      <inertia ixx="0.221974079052602" ixy="-0.141507050941171" ixz="0.0301561812700284" iyy="0.939162032493568" iyz="0.0192441089513427" izz="0.961901906934015"/>
    </inertial>
    <visual>
      <origin rpy="0 0 0" xyz="0 0 0"/>
      <geometry>
        <mesh filename="package://m545_description/meshes/simplified/swivel_rl_link.STL"/>
      </geometry>
      <material name="">
        <color rgba="0.752941176470588 0.752941176470588 0.752941176470588 1"/>
      </material>
    </visual>
    <collision>
      <origin rpy="0 0 0" xyz="0 0 0"/>
      <geometry>
        <mesh filename="package://m545_description/meshes/convexhull/swivel_rl_link.STL"/>
      </geometry>
    </collision>
  </link>
  <joint name="swivel_rl" type="revolute">
    <origin rpy="-1.5708 0 0" xyz="0.205 0.12 0.102"/>
    <parent link="arter/stabilizer_rl_link"/>
    <child link="arter/swivel_rl_link"/>
    <axis xyz="0 0 1"/>
    <limit effort="1200000" lower="-0.69" upper="0.56" velocity="1"/>
  </joint>
  <link name="arter/steering_rl_link">
    <inertial>
      <origin rpy="0 0 0" xyz="0.378433093119463 -0.0612909400686655 0.0602966364167291"/>
      <mass value="19.7026972877348"/>
      <inertia ixx="0.364033643803981" ixy="0.00721287223255834" ixz="0.00363307812574056" iyy="0.374202380615645" iyz="0.00143271329407031" izz="0.406474676800037"/>
    </inertial>
    <visual>
      <origin rpy="0 0 0" xyz="0 0 0"/>
      <geometry>
        <mesh filename="package://m545_description/meshes/simplified/steering_rl_link.STL"/>
      </geometry>
      <material name="">
        <color rgba="0.752941176470588 0.752941176470588 0.752941176470588 1"/>
      </material>
    </visual>
    <collision>
      <origin rpy="0 0 0" xyz="0 0 0"/>
      <geometry>
        <mesh filename="package://m545_description/meshes/convexhull/steering_rl_link.STL"/>
      </geometry>
    </collision>
  </link>
  <joint name="steering_rl" type="revolute">
    <origin rpy="0 0 0" xyz="0.975 0 -0.045"/>
    <parent link="arter/swivel_rl_link"/>
    <child link="arter/steering_rl_link"/>
    <axis xyz="0 0 1"/>
    <limit effort="1200000" lower="-1.2" upper="1.2" velocity="1"/>
  </joint>
  <link name="arter/wheel_rl_link">
    <inertial>
      <origin rpy="0 0 0" xyz="-9.366E-05 0.00044036 0.10281"/>
      <mass value="154.12"/>
      <inertia ixx="18.906" ixy="0.00092354" ixz="0.0013107" iyy="18.905" iyz="0.002858" izz="28.635"/>
    </inertial>
    <visual>
      <origin rpy="0 0 0" xyz="0 0 0"/>
      <geometry>
        <mesh filename="package://m545_description/meshes/simplified/wheel_rl_link.dae"/>
      </geometry>
      <material name="">
        <color rgba="0.75294 0.75294 0.75294 1"/>
      </material>
    </visual>
    <collision>
      <origin rpy="0 0 0" xyz="0 0 0"/>
      <geometry>
        <mesh filename="package://m545_description/meshes/convexhull/wheel_rl_link.STL" scale="1.1 1.1 1.1"/>
      </geometry>
    </collision>
  </link>
  <joint name="wheel_rl" type="continuous">
    <origin rpy="1.5708 0 0" xyz="0.5 -0.398 0.0305"/>
    <parent link="arter/steering_rl_link"/>
    <child link="arter/wheel_rl_link"/>
    <axis xyz="0 0 1"/>
    <limit effort="1200000" velocity="10"/>
  </joint>
  <link name="arter/mountain_stabilizer_rl_angular_link">
    <inertial>
      <origin rpy="0 0 0" xyz="0.27239 -0.092388 0.0014976"/>
      <mass value="5.7065"/>
      <inertia ixx="0.023135" ixy="0.012663" ixz="-0.00023247" iyy="0.12901" iyz="0.00030086" izz="0.14539"/>
    </inertial>
    <visual>
      <origin rpy="0 0 0" xyz="0 0 0"/>
      <geometry>
        <mesh filename="package://m545_description/meshes/simplified/mountain_stabilizer_rl_angular_link.STL"/>
      </geometry>
      <material name="">
        <color rgba="0.75294 0.75294 0.75294 1"/>
      </material>
    </visual>
    <collision>
      <origin rpy="0 0 0" xyz="0 0 0"/>
      <geometry>
        <mesh filename="package://m545_description/meshes/convexhull/mountain_stabilizer_rl_angular_link.STL"/>
      </geometry>
    </collision>
  </link>
  <joint name="claw_dipper_rl" type="revolute">
    <origin rpy="1.5892 -1.2217 0" xyz="0.79213 -0.019 -0.010556"/>
    <parent link="arter/steering_rl_link"/>
    <child link="arter/mountain_stabilizer_rl_angular_link"/>
    <axis xyz="0 0 1"/>
    <limit effort="1200000" lower="-1.6" upper="0.01" velocity="1"/>
  </joint>
  <link name="arter/mountain_stabilizer_rl_linear_link">
    <inertial>
      <origin rpy="0 0 0" xyz="-0.029771 -1.3396E-07 0.48877"/>
      <mass value="8.7792"/>
      <inertia ixx="0.16159" ixy="2.9894E-08" ixz="-0.03096" iyy="0.15075" iyz="-4.6179E-09" izz="0.1029"/>
    </inertial>
    <visual>
      <origin rpy="0 0 0" xyz="0 0 0"/>
      <geometry>
        <mesh filename="package://m545_description/meshes/simplified/mountain_stabilizer_rl_linear_link.STL"/>
      </geometry>
      <material name="">
        <color rgba="0.75294 0.75294 0.75294 1"/>
      </material>
    </visual>
    <collision>
      <origin rpy="0 0 0" xyz="0 0 0"/>
      <geometry>
        <mesh filename="package://m545_description/meshes/convexhull/mountain_stabilizer_rl_linear_link.STL"/>
      </geometry>
    </collision>
  </link>
  <joint name="claw_telescope_rl" type="prismatic">
    <origin rpy="1.5708 0.018356 1.5708" xyz="0.10861 -0.14373 0.0026385"/>
    <parent link="arter/mountain_stabilizer_rl_angular_link"/>
    <child link="arter/mountain_stabilizer_rl_linear_link"/>
    <axis xyz="0 0 1"/>
    <limit effort="1200000" lower="-0.01" upper="0.75" velocity="0.2"/>
  </joint>
  <link name="arter/stabilizer_rr_link">
    <inertial>
      <origin rpy="0 0 0" xyz="0.0882179106149161 0.140055766746372 -0.00277592352370326"/>
      <mass value="13.9599590912902"/>
      <inertia ixx="0.160009064402167" ixy="0.00339485163227222" ixz="-0.000294202137004026" iyy="0.11860736720373" iyz="-0.00164260988618627" izz="0.0975616232921858"/>
    </inertial>
    <visual>
      <origin rpy="0 0 0" xyz="0 0 0"/>
      <geometry>
        <mesh filename="package://m545_description/meshes/simplified/stabilizer_rr_link.STL"/>
      </geometry>
      <material name="">
        <color rgba="0.752941176470588 0.752941176470588 0.752941176470588 1"/>
      </material>
    </visual>
    <collision>
      <origin rpy="0 0 0" xyz="0 0 0"/>
      <geometry>
        <mesh filename="package://m545_description/meshes/convexhull/stabilizer_rr_link.STL"/>
      </geometry>
    </collision>
  </link>
  <joint name="stabilizer_rr" type="revolute">
    <origin rpy="1.5708 0 -3.1416" xyz="-0.64 -0.755 0.06"/>
    <parent link="arter/base_link"/>
    <child link="arter/stabilizer_rr_link"/>
    <axis xyz="0 0 1"/>
    <limit effort="1200000" lower="-0.77" upper="0.27" velocity="1"/>
  </joint>
  <link name="arter/swivel_rr_link">
    <inertial>
      <origin rpy="0 0 0" xyz="0.510332651905848 -0.0805008665227143 -0.0112724285315606"/>
      <mass value="22.0661010806813"/>
      <inertia ixx="0.222081504689202" ixy="0.140951297095676" ixz="0.0301560723224572" iyy="0.937062386189872" iyz="-0.0192440140515883" izz="0.959908969427251"/>
    </inertial>
    <visual>
      <origin rpy="0 0 0" xyz="0 0 0"/>
      <geometry>
        <mesh filename="package://m545_description/meshes/simplified/swivel_rr_link.STL"/>
      </geometry>
      <material name="">
        <color rgba="0.752941176470588 0.752941176470588 0.752941176470588 1"/>
      </material>
    </visual>
    <collision>
      <origin rpy="0 0 0" xyz="0 0 0"/>
      <geometry>
        <mesh filename="package://m545_description/meshes/convexhull/swivel_rr_link.STL"/>
      </geometry>
    </collision>
  </link>
  <joint name="swivel_rr" type="revolute">
    <origin rpy="-1.5708 0 0" xyz="0.205 0.12 -0.102"/>
    <parent link="arter/stabilizer_rr_link"/>
    <child link="arter/swivel_rr_link"/>
    <axis xyz="0 0 1"/>
    <limit effort="1200000" lower="-0.69" upper="0.57" velocity="1"/>
  </joint>
  <link name="arter/steering_rr_link">
    <inertial>
      <origin rpy="0 0 0" xyz="0.378430589989904 0.0612916098400371 0.0602967726085394"/>
      <mass value="19.7026960516809"/>
      <inertia ixx="0.364033677089712" ixy="-0.0072127974836079" ixz="0.00363316220801541" iyy="0.374202363583879" iyz="-0.00143247606987954" izz="0.406474569177028"/>
    </inertial>
    <visual>
      <origin rpy="0 0 0" xyz="0 0 0"/>
      <geometry>
        <mesh filename="package://m545_description/meshes/simplified/steering_rr_link.STL"/>
      </geometry>
      <material name="">
        <color rgba="0.752941176470588 0.752941176470588 0.752941176470588 1"/>
      </material>
    </visual>
    <collision>
      <origin rpy="0 0 0" xyz="0 0 0"/>
      <geometry>
        <mesh filename="package://m545_description/meshes/convexhull/steering_rr_link.STL"/>
      </geometry>
    </collision>
  </link>
  <joint name="steering_rr" type="revolute">
    <origin rpy="0 0 0" xyz="0.975 0 -0.045"/>
    <parent link="arter/swivel_rr_link"/>
    <child link="arter/steering_rr_link"/>
    <axis xyz="0 0 1"/>
    <limit effort="1200000" lower="-1.2" upper="1.2" velocity="1"/>
  </joint>
  <link name="arter/wheel_rr_link">
    <inertial>
      <origin rpy="0 0 0" xyz="-0.00010451 0.00046801 0.0565"/>
      <mass value="154.12"/>
      <inertia ixx="18.907" ixy="0.0015541" ixz="0.00056283" iyy="18.904" iyz="0.0020785" izz="28.635"/>
    </inertial>
    <visual>
      <origin rpy="0 0 0" xyz="0 0 0"/>
      <geometry>
        <mesh filename="package://m545_description/meshes/simplified/wheel_rr_link.dae"/>
      </geometry>
      <material name="">
        <color rgba="0.75294 0.75294 0.75294 1"/>
      </material>
    </visual>
    <collision>
      <origin rpy="0 0 0" xyz="0 0 0"/>
      <geometry>
        <mesh filename="package://m545_description/meshes/convexhull/wheel_rr_link.STL" scale="1.1 1.1 1.1"/>
      </geometry>
    </collision>
  </link>
  <joint name="wheel_rr" type="continuous">
    <origin rpy="-1.5708 0 0" xyz="0.5 0.398 0.0305"/>
    <parent link="arter/steering_rr_link"/>
    <child link="arter/wheel_rr_link"/>
    <axis xyz="0 0 1"/>
    <limit effort="1200000" velocity="10"/>
  </joint>
  <link name="arter/mountain_stabilizer_rr_angular_link">
    <inertial>
      <origin rpy="0 0 0" xyz="0.27239 -0.092371 -0.002321"/>
      <mass value="5.7065"/>
      <inertia ixx="0.023135" ixy="0.012662" ixz="0.00029094" iyy="0.12901" iyz="-0.00037653" izz="0.14539"/>
    </inertial>
    <visual>
      <origin rpy="0 0 0" xyz="0 0 0"/>
      <geometry>
        <mesh filename="package://m545_description/meshes/simplified/mountain_stabilizer_rr_angular_link.STL"/>
      </geometry>
      <material name="">
        <color rgba="0.75294 0.75294 0.75294 1"/>
      </material>
    </visual>
    <collision>
      <origin rpy="0 0 0" xyz="0 0 0"/>
      <geometry>
        <mesh filename="package://m545_description/meshes/convexhull/mountain_stabilizer_rr_angular_link.STL"/>
      </geometry>
    </collision>
  </link>
  <joint name="claw_dipper_rr" type="revolute">
    <origin rpy="1.5478 -1.2217 0" xyz="0.79213 0.019 -0.010556"/>
    <parent link="arter/steering_rr_link"/>
    <child link="arter/mountain_stabilizer_rr_angular_link"/>
    <axis xyz="0 0 1"/>
    <limit effort="1200000" lower="-1.6" upper="0.01" velocity="1"/>
  </joint>
  <link name="arter/mountain_stabilizer_rr_linear_link">
    <inertial>
      <origin rpy="0 0 0" xyz="-0.029771 -1.3396E-07 0.48877"/>
      <mass value="8.7792"/>
      <inertia ixx="0.16159" ixy="2.9894E-08" ixz="-0.03096" iyy="0.15075" iyz="-4.6179E-09" izz="0.1029"/>
    </inertial>
    <visual>
      <origin rpy="0 0 0" xyz="0 0 0"/>
      <geometry>
        <mesh filename="package://m545_description/meshes/simplified/mountain_stabilizer_rr_linear_link.STL"/>
      </geometry>
      <material name="">
        <color rgba="0.75294 0.75294 0.75294 1"/>
      </material>
    </visual>
    <collision>
      <origin rpy="0 0 0" xyz="0 0 0"/>
      <geometry>
        <mesh filename="package://m545_description/meshes/convexhull/mountain_stabilizer_rr_linear_link.STL"/>
      </geometry>
    </collision>
  </link>
  <joint name="claw_telescope_rr" type="prismatic">
    <origin rpy="1.5708 -0.022974 1.5708" xyz="0.10861 -0.14371 -0.0033022"/>
    <parent link="arter/mountain_stabilizer_rr_angular_link"/>
    <child link="arter/mountain_stabilizer_rr_linear_link"/>
    <axis xyz="0 0 1"/>
    <limit effort="1200000" lower="-0.01" upper="0.75" velocity="0.2"/>
  </joint>
  <!-- Please make sure give a prefix before calling this file -->
  <!-- Options for mesh quality: high_res, simplified, convexhull -->
  <link name="arter/wide_shovel_base_link">
    <inertial>
      <!-- <origin xyz="0.2886 -0.43638 -0.00041101" rpy="0 3.14159265359 0 "/> -->
      <origin rpy="0 3.14159265359 0 " xyz="0.6386 -0.43638 -0.00041101"/>
      <mass value="53.003"/>
      <inertia ixx="7.8809" ixy="-0.49851" ixz="-2.8223E-05" iyy="7.811" iyz="-3.7473E-05" izz="1.8415"/>
    </inertial>
    <visual>
      <origin rpy="0 3.14159265359 0" xyz="0.35 0 0"/>
      <geometry>
        <mesh filename="package://wide_shovel_description/meshes/simplified/wide_shovel_base_link.STL"/>
      </geometry>
      <material name="">
        <color rgba="0.75294 0.75294 0.75294 1"/>
      </material>
    </visual>
    <collision>
      <origin rpy="0 0 0" xyz="0 0 0"/>
      <geometry>
        <mesh filename="package://wide_shovel_description/meshes/convexhull/wide_shovel_base_link.STL"/>
      </geometry>
    </collision>
  </link>
  <link name="arter/wide_shovel_bottom_link">
    <inertial>
      <origin rpy="0 0 0" xyz="0.51546 0.00041094 0.3058"/>
      <mass value="0"/>
      <inertia ixx="0" ixy="0" ixz="0" iyy="0" iyz="0" izz="0"/>
    </inertial>
  </link>
  <joint name="wide_shovel_bottom_joint_fixed" type="fixed">
    <origin rpy="-1.5708 0 0.24435" xyz="-0.13757 -0.8578 0"/>
    <parent link="arter/wide_shovel_base_link"/>
    <child link="arter/wide_shovel_bottom_link"/>
    <axis xyz="0 0 0"/>
  </joint>
  <joint name="wide_shovel_fixed_joint" type="fixed">
    <parent link="arter/tool_link"/>
    <child link="arter/wide_shovel_base_link"/>
  </joint>
</robot>
